<robot name="simplecar">
    <!-- Colors --> 
    <material name="black"> 
        <color rgba="0 0 0 1"/>
    </material>
    <material name="blue"> 
        <color rgba="0.6 0.7 0.8 1"/>
    </material>
    <material name="red"> 
        <color rgba="0.2 0.1 0.8 1"/>
    </material>
    <material name="dark"> 
        <color rgba="0.5 0.3 0.8 1"/>
    </material>

    <!-- Base Frame of Car --> 
    <link name="base_link">
        <visual> 
            <geometry> 
                <box size="0.5 0.3 0.4"/>
            </geometry>
            <material name="blue"/>
        </visual>
        <collision>
            <geometry> 
                <box size="0.5 0.3 0.4"/>
            </geometry>

         </collision>
        <inertial> 
            <mass value="3"/>
            <inertia ixx="0.2" ixy="0" ixz="0" iyy="0.2" iyz="0.0" izz="0.2"/>
        </inertial> 
    </link> 


  <link name = "male">
      <visual>
       <geometry> 
                <cylinder length="0.05" radius="0.1"/>
            </geometry>
            <origin rpy="0 1.57 0"/>
            <material name="red"/>
        </visual>
        <collision> 
             <geometry> 
                <cylinder length="0.05" radius="0.1"/>
            </geometry>
            <origin rpy="0 1.57 0"/>
        </collision> 
        <inertial> 
            <origin rpy="0 1.57 0"/>
            <mass value="0"/>
            <inertia ixx="0.4" ixy="0" ixz="0" iyy="0.4" iyz="0.0" izz="0.2"/>
        </inertial> 
    </link> 

    <joint name="male_base" type="continuous">
        <parent link="base_link"/>
        <child link="male"/> 
        <axis xyz="0 0 1"/>
        <origin xyz="0.25 0 0"/>
    </joint>


  <link name = "female">
      <visual>
       <geometry> 
                <cylinder length="0.05" radius="0.1"/>
            </geometry>
            <origin rpy="0 1.57 0"/>
            <material name="dark"/>
        </visual>
        <collision> 
             <geometry> 
                <cylinder length="0.05" radius="0.1"/>
            </geometry>
            <origin rpy="0 1.57 0"/>
        </collision> 
        <inertial> 
            <origin rpy="0 1.57 0"/>
            <mass value="0"/>
            <inertia ixx="0.4" ixy="0" ixz="0" iyy="0.4" iyz="0.0" izz="0.2"/>
        </inertial> 
    </link> 

    <joint name="female_base" type="continuous">
        <parent link="base_link"/>
        <child link="female"/> 
        <axis xyz="1 0 0"/>
        <origin xyz="-0.275 0 0"/>
    </joint>




    
    <link name="hook">
        <visual> 
            <geometry> 
                <box size="0.05 0.01 0.01"/>
            </geometry>
            <material name="blue"/>
        </visual>
        <collision>
              <geometry> 
                <box size="0.05 0.01 0.01"/>
            </geometry>

        </collision>
       
        <inertial> 
            <mass value="0"/>
            <inertia ixx="0.2" ixy="0" ixz="0" iyy="0.2" iyz="0.0" izz="0.2"/>
        </inertial> 
       
    </link> 

  
   <joint name="hook_body" type = "continuous">
   <parent link = "female"/>
    <child link= "hook"/>
    <axis xyz = "1 0 0"/>
    <origin xyz = "-0.05 0 0"/>
   </joint>

 <link name= "hookup" >
        <visual> 
            <geometry> 
                <box size="0.01 0.01 0.03"/>
            </geometry>
            <material name="blue"/>
        </visual>

        <collision>
           <geometry> 
                <box size="0.01 0.01 0.03"/>
            </geometry>
        </collision>
        <inertial> 
            <mass value="0"/>
            <inertia ixx="0.2" ixy="0" ixz="0" iyy="0.2" iyz="0.0" izz="0.2"/>
        </inertial> 
       
    </link> 
   
     <joint name = "Hook1" type = "fixed">
      <parent link="hook"/>
        <child link="hookup"/> 
        <origin xyz="-0.017 0 0.02"/>


     </joint>

   
 <!-- Left Back Wheel -->
    <link name="left_back_wheel">
        <visual> 
            <geometry> 
                <cylinder length="0.05" radius="0.1"/>
            </geometry>
            <origin rpy="1.57075 1.57075 -0.2"/>
            <material name="black"/>
        </visual>
        <collision> 
             <geometry> 
                <cylinder length="0.05" radius="0.1"/>
            </geometry>
            <origin rpy="1.57075 1.57075 -0.2"/>
        </collision> 
        <inertial> 
            <origin rpy="1.57075 1.57075 -0.2"/>
            <mass value="0.7"/>
            <inertia ixx="0.4" ixy="0" ixz="0" iyy="0.4" iyz="0.0" izz="0.2"/>
        </inertial> 
    </link> 
    <joint name="base_to_left_back_wheel" type="continuous">
        <parent link="base_link"/>
        <child link="left_back_wheel"/> 
        <axis xyz="0 1 0"/>
        <origin xyz="0 0.175 -0.2"/>
    </joint>
   



  <!-- Right Back Wheel -->
    <link name="right_back_wheel">
        <visual> 
            <geometry> 
                <cylinder length="0.05" radius="0.1"/>
            </geometry>
            <origin rpy="-1.57075 -1.57075 -0.2"/>
            <material name="black"/>
        </visual>
        <collision> 
             <geometry> 
                <cylinder length="0.05" radius="0.1"/>
            </geometry>
            <origin rpy="-1.57075 -1.57075 -0.2"/>
        </collision> 
        <inertial> 
            <origin rpy="-1.57075 -1.57075 -0.2"/>
            <mass value="0.7"/>
            <inertia ixx="0.4" ixy="0" ixz="0" iyy="0.4" iyz="0.0" izz="0.2"/>
        </inertial> 
    </link> 
    <joint name="base_to_right_back_wheel" type="continuous">
        <parent link="base_link"/>
        <child link="right_back_wheel"/> 
        <axis xyz="0 1 0"/>
        <origin xyz="0 -0.175 -0.2"/>
    </joint>

</robot>
