<?xml version="1.0" encoding="utf-8"?>
<!-- This URDF was automatically created by SolidWorks to URDF Exporter! Originally created by Stephen Brawner (brawner@gmail.com) 
     Commit Version: 1.6.0-1-g15f4949  Build Version: 1.6.7594.29634
     For more information, please see http://wiki.ros.org/sw_urdf_exporter -->
<robot
  name="iota">
  <material name="White">
	<color
          rgba="1.0 1.0 1.0 0.32" />
  </material>
  <material name="Green">
	<color
          rgba="0.18 0.72 0.18 1.0" />
  </material>
  <material name="Black">
	<color
          rgba="0.1 0.1 0.1 1.0" />
  </material>
  <material name="Red">
	<color rgba="1.0 0.2 0.0 0.7" />
  </material>
  <material name="LBlue">
	<color rgba="0.2 0.4 1.0 1.0" />
  </material>
  <material name="DBlue">
  <color rgba="0.0 0.0 1.0 1.0" />
  </material>
  <link
    name="base_link">
    <inertial>
      <origin
        xyz="0.0157046714219995 -0.0486777315109957 0.0326730100469145"
        rpy="0 0 0" />
      <mass
        value="0.00602026598183142" />
      <inertia
        ixx="1.29548409457843E-06"
        ixy="1.82692972019999E-13"
        ixz="2.35543979474496E-23"
        iyy="9.46213258006389E-07"
        iyz="-6.69716828985188E-23"
        izz="2.2354681429883E-06" />
    </inertial>
    <visual>
      <origin
        xyz="0 0 0"
        rpy="0 0 0" />
      <geometry>
        <mesh
          filename="meshes/base_link.STL" />
      </geometry>
      <material
        name="White"/>
    </visual>
    <collision>
      <origin
        xyz="0 0 0"
        rpy="0 0 0" />
      <geometry>
        <mesh
          filename="meshes/base_link.STL" />
      </geometry>
    </collision>
  </link>
  <link
    name="dbr_motor">
    <inertial>
      <origin
        xyz="0.0180465410708374 0.0055 -0.0104996579668553"
        rpy="0 0 0" />
      <mass
        value="0.000645828982770904" />
      <inertia
        ixx="2.61519018844216E-08"
        ixy="-3.7038731854198E-26"
        ixz="-3.37174308525786E-25"
        iyy="2.61519018844216E-08"
        iyz="-5.17287894601584E-25"
        izz="2.86716606772477E-09" />
    </inertial>
    <visual>
      <origin
        xyz="0 0 0"
        rpy="0 0 0" />
      <geometry>
        <mesh
          filename="meshes/dbr_motor.STL" />
      </geometry>
      <material
        name="Green"/>
    </visual>
    <collision>
      <origin
        xyz="0 0 0"
        rpy="0 0 0" />
      <geometry>
        <mesh
          filename="meshes/dbr_motor.STL" />
      </geometry>
    </collision>
  </link>
  <joint
    name="dbr_motor"
    type="fixed">
    <origin
      xyz="0.0157046714219995 -0.0486777315109957 0.0313985670725845"
      rpy="1.5707963267949 0 0" />
    <parent
      link="base_link" />
    <child
      link="dbr_motor" />
    <axis
      xyz="0 0 0" />
  </joint>
  <link
    name="dbr_wheel">
    <inertial>
      <origin
        xyz="0 0 0.0025"
        rpy="0 0 0" />
      <mass
        value="0.000681713039458371" />
      <inertia
        ixx="8.90885323732181E-09"
        ixy="-6.20385459414771E-25"
        ixz="-4.15182492378448E-25"
        iyy="8.90885323732181E-09"
        iyz="-2.94650062225219E-26"
        izz="1.49772354769004E-08" />
    </inertial>
    <visual>
      <origin
        xyz="0 0 0"
        rpy="0 0 0" />
      <geometry>
        <mesh
          filename="meshes/dbr_wheel.STL" />
      </geometry>
      <material
        name="Black"/>
    </visual>
    <collision>
      <origin
        xyz="0 0 0"
        rpy="0 0 0" />
      <geometry>
        <mesh
          filename="meshes/dbr_wheel.STL" />
      </geometry>
    </collision>
  </link>
  <joint
    name="dbr_wheel"
    type="continuous">
    <origin
      xyz="0.0180465410708374 0.0055 -0.0258126052667903"
      rpy="0 0 -0.151232003284142" />
    <parent
      link="dbr_motor" />
    <child
      link="dbr_wheel" />
    <axis
      xyz="0 0 1" />
  </joint>
  <link
    name="dbl_motor">
    <inertial>
      <origin
        xyz="0 0 0.0106870527000651"
        rpy="0 0 0" />
      <mass
        value="0.000645828982770904" />
      <inertia
        ixx="2.61519018844216E-08"
        ixy="0"
        ixz="-6.18543725057378E-25"
        iyy="2.61519018844216E-08"
        iyz="-8.993865166459E-26"
        izz="2.86716606772477E-09" />
    </inertial>
    <visual>
      <origin
        xyz="0 0 0"
        rpy="0 0 0" />
      <geometry>
        <mesh
          filename="meshes/dbl_motor.STL" />
      </geometry>
      <material
        name="Green"/>
    </visual>
    <collision>
      <origin
        xyz="0 0 0"
        rpy="0 0 0" />
      <geometry>
        <mesh
          filename="meshes/dbl_motor.STL" />
      </geometry>
    </collision>
  </link>
  <joint
    name="dbl_motor"
    type="fixed">
    <origin
      xyz="0.0337512124928369 -0.0488651262442055 0.0368985670725845"
      rpy="1.5707963267949 -0.344784457208072 0" />
    <parent
      link="base_link" />
    <child
      link="dbl_motor" />
    <axis
      xyz="0 0 0" />
  </joint>
  <link
    name="dbl_wheel">
    <inertial>
      <origin
        xyz="0 0 0.0025"
        rpy="0 0 0" />
      <mass
        value="0.000681713039458372" />
      <inertia
        ixx="8.90885323732183E-09"
        ixy="-2.06795153138257E-25"
        ixz="5.81366113987744E-25"
        iyy="8.90885323732183E-09"
        iyz="1.67751780996211E-28"
        izz="1.49772354769004E-08" />
    </inertial>
    <visual>
      <origin
        xyz="0 0 0"
        rpy="0 0 0" />
      <geometry>
        <mesh
          filename="meshes/dbl_wheel.STL" />
      </geometry>
      <material
        name="Black"/>
    </visual>
    <collision>
      <origin
        xyz="0 0 0"
        rpy="0 0 0" />
      <geometry>
        <mesh
          filename="meshes/dbl_wheel.STL" />
      </geometry>
    </collision>
  </link>
  <joint
    name="dbl_wheel"
    type="continuous">
    <origin
      xyz="0 0 0.021"
      rpy="0 0 -0.528472588992204" />
    <parent
      link="dbl_motor" />
    <child
      link="dbl_wheel" />
    <axis
      xyz="0 0 1" />
  </joint>
  <link
    name="dfr_motor">
    <inertial>
      <origin
        xyz="0 -3.46944695195361E-18 0.0106870527000651"
        rpy="0 0 0" />
      <mass
        value="0.000645828982770904" />
      <inertia
        ixx="2.61519018844216E-08"
        ixy="0"
        ixz="-2.37221797541323E-24"
        iyy="2.61519018844216E-08"
        iyz="1.94736245006016E-24"
        izz="2.86716606772477E-09" />
    </inertial>
    <visual>
      <origin
        xyz="0 0 0"
        rpy="0 0 0" />
      <geometry>
        <mesh
          filename="meshes/dfr_motor.STL" />
      </geometry>
      <material
        name="Green"/>
    </visual>
    <collision>
      <origin
        xyz="0 0 0"
        rpy="0 0 0" />
      <geometry>
        <mesh
          filename="meshes/dfr_motor.STL" />
      </geometry>
    </collision>
  </link>
  <joint
    name="dfr_motor"
    type="fixed">
    <origin
      xyz="-0.00164838652382185 -0.0491355291275451 0.0368985670725845"
      rpy="1.5707963267949 -0.890920085389358 3.14159265358979" />
    <parent
      link="base_link" />
    <child
      link="dfr_motor" />
    <axis
      xyz="0 0 0" />
  </joint>
  <link
    name="dfr_wheel">
    <inertial>
      <origin
        xyz="1.73472347597681E-18 -6.93889390390723E-18 -0.0025"
        rpy="0 0 0" />
      <mass
        value="0.000681713039458371" />
      <inertia
        ixx="8.90885323732182E-09"
        ixy="-5.16987882845642E-25"
        ixz="6.61424870729911E-25"
        iyy="8.90885323732182E-09"
        iyz="1.75987313302614E-25"
        izz="1.49772354769004E-08" />
    </inertial>
    <visual>
      <origin
        xyz="0 0 0"
        rpy="0 0 0" />
      <geometry>
        <mesh
          filename="meshes/dfr_wheel.STL" />
      </geometry>
      <material
        name="Black"/>
    </visual>
    <collision>
      <origin
        xyz="0 0 0"
        rpy="0 0 0" />
      <geometry>
        <mesh
          filename="meshes/dfr_wheel.STL" />
      </geometry>
    </collision>
  </link>
  <joint
    name="dfr_wheel"
    type="continuous">
    <origin
      xyz="0 0 0.021"
      rpy="3.14159265358979 0 2.42846104804575" />
    <parent
      link="dfr_motor" />
    <child
      link="dfr_wheel" />
    <axis
      xyz="0 0 1" />
  </joint>
  <link
    name="dfl_motor">
    <inertial>
      <origin
        xyz="6.7762635780344E-18 -7.63278329429795E-17 0.0106870527000651"
        rpy="0 0 0" />
      <mass
        value="0.000645828982770904" />
      <inertia
        ixx="2.61519018844216E-08"
        ixy="5.93486893921018E-39"
        ixz="-3.17179904389924E-23"
        iyy="2.61519018844216E-08"
        iyz="-3.23352476560176E-23"
        izz="2.86716606772477E-09" />
    </inertial>
    <visual>
      <origin
        xyz="0 0 0"
        rpy="0 0 0" />
      <geometry>
        <mesh
          filename="meshes/dfl_motor.STL" />
      </geometry>
      <material
        name="Green"/>
    </visual>
    <collision>
      <origin
        xyz="0 0 0"
        rpy="0 0 0" />
      <geometry>
        <mesh
          filename="meshes/dfl_motor.STL" />
      </geometry>
    </collision>
  </link>
  <joint
    name="dfl_motor"
    type="fixed">
    <origin
      xyz="-0.00164838652382185 -0.0491355291275451 0.0368985670725845"
      rpy="1.5707963267949 -0.0567673670058903 0" />
    <parent
      link="base_link" />
    <child
      link="dfl_motor" />
    <axis
      xyz="0 0 0" />
  </joint>
  <link
    name="dfl_wheel">
    <inertial>
      <origin
        xyz="2.82543086149722E-16 0 0.0025"
        rpy="0 0 0" />
      <mass
        value="0.000681713039458372" />
      <inertia
        ixx="8.90885323732182E-09"
        ixy="-1.83332255573151E-43"
        ixz="-7.87233226798591E-41"
        iyy="8.90885323732182E-09"
        iyz="-2.31915303300036E-41"
        izz="1.49772354769004E-08" />
    </inertial>
    <visual>
      <origin
        xyz="0 0 0"
        rpy="0 0 0" />
      <geometry>
        <mesh
          filename="meshes/dfl_wheel.STL" />
      </geometry>
      <material
        name="Black"/>
    </visual>
    <collision>
      <origin
        xyz="0 0 0"
        rpy="0 0 0" />
      <geometry>
        <mesh
          filename="meshes/dfl_wheel.STL" />
      </geometry>
    </collision>
  </link>
  <joint
    name="dfl_wheel"
    type="continuous">
    <origin
      xyz="0 0 0.021"
      rpy="0 0 -0.0567673670058903" />
    <parent
      link="dfl_motor" />
    <child
      link="dfl_wheel" />
    <axis
      xyz="0 0 1" />
  </joint>
  <link
    name="r_plate">
    <inertial>
      <origin
        xyz="0.036453781512605 0.0225 0.001"
        rpy="0 0 0" />
      <mass
        value="0.00563834139292078" />
      <inertia
        ixx="9.18566945337333E-07"
        ixy="-2.20216452907176E-07"
        ixz="3.9955266293099E-24"
        iyy="1.67797643505038E-06"
        iyz="1.30040278787411E-24"
        izz="2.59278448612577E-06" />
    </inertial>
    <visual>
      <origin
        xyz="0 0 0"
        rpy="0 0 0" />
      <geometry>
        <mesh
          filename="meshes/r_plate.STL" />
      </geometry>
      <material
        name="White"/>
    </visual>
    <collision>
      <origin
        xyz="0 0 0"
        rpy="0 0 0" />
      <geometry>
        <mesh
          filename="meshes/r_plate.STL" />
      </geometry>
    </collision>
  </link>
  <joint
    name="r_plate"
    type="fixed">
    <origin
      xyz="-0.0156361653843612 -0.0186777315109957 0.0338985670725845"
      rpy="1.5707963267949 0 0" />
    <parent
      link="base_link" />
    <child
      link="r_plate" />
    <axis
      xyz="0 0 0" />
  </joint>
  <link
    name="lower_pin">
    <inertial>
      <origin
        xyz="1.8357600118171E-07 -3.46181416865932E-14 0.027899999999396"
        rpy="0 0 0" />
      <mass
        value="0.000238824" />
      <inertia
        ixx="6.20472712773207E-08"
        ixy="-1.49698236656339E-24"
        ixz="-4.07210097102362E-13"
        iyy="6.204727128E-08"
        iyz="7.67734671986729E-20"
        izz="1.59216002679355E-10" />
    </inertial>
    <visual>
      <origin
        xyz="0 0 0"
        rpy="0 0 0" />
      <geometry>
        <mesh
          filename="meshes/lower_pin.STL" />
      </geometry>
      <material
        name="Red"/>
    </visual>
    <collision>
      <origin
        xyz="0 0 0"
        rpy="0 0 0" />
      <geometry>
        <mesh
          filename="meshes/lower_pin.STL" />
      </geometry>
    </collision>
  </link>
  <joint
    name="lower_pin"
    type="fixed">
    <origin
      xyz="0.028589 0.013247 0.0031239"
      rpy="0.057254 0 -0.27933" />
    <parent
      link="r_plate" />
    <child
      link="lower_pin" />
    <axis
      xyz="0 0 0" />
  </joint>
  <link
    name="f_servo">
    <inertial>
      <origin
        xyz="-0.00036971682008817 -3.52395606977654E-05 -0.00131147866176589"
        rpy="0 0 0" />
      <mass
        value="0.00677100575579448" />
      <inertia
        ixx="4.31149666383789E-07"
        ixy="8.82221194039352E-11"
        ixz="-3.10904728009683E-08"
        iyy="6.71938564058982E-07"
        iyz="1.06335363009129E-09"
        izz="3.91967417754935E-07" />
    </inertial>
    <visual>
      <origin
        xyz="0 0 0"
        rpy="0 0 0" />
      <geometry>
        <mesh
          filename="meshes/f_servo.STL" />
      </geometry>
      <material
        name="DBlue"/>
    </visual>
    <collision>
      <origin
        xyz="0 0 0"
        rpy="0 0 0" />
      <geometry>
        <mesh
          filename="meshes/f_servo.STL" />
      </geometry>
    </collision>
  </link>
  <joint
    name="f_servo"
    type="fixed">
    <origin
      xyz="-0.00327850155878186 0.00710820887028432 0.0211565538865111"
      rpy="0 1.5707963267949 0" />
    <parent
      link="lower_pin" />
    <child
      link="f_servo" />
    <axis
      xyz="0 0 0" />
  </joint>
  <link
    name="f_dock">
    <inertial>
      <origin
        xyz="-0.000583720901506664 -3.46944695195361E-17 0.000597711827388714"
        rpy="0 0 0" />
      <mass
        value="0.000956519229010847" />
      <inertia
        ixx="3.43726720881399E-08"
        ixy="3.10192729707385E-25"
        ixz="9.6412822802805E-10"
        iyy="3.45134904910005E-08"
        iyz="-2.78535387045169E-24"
        izz="6.75077500977736E-08" />
    </inertial>
    <visual>
      <origin
        xyz="0 0 0"
        rpy="0 0 0" />
      <geometry>
        <mesh
          filename="meshes/f_dock.STL" />
      </geometry>
      <material
        name="LBlue"/>
    </visual>
    <collision>
      <origin
        xyz="0 0 0"
        rpy="0 0 0" />
      <geometry>
        <mesh
          filename="meshes/f_dock.STL" />
      </geometry>
    </collision>
  </link>
  <joint
    name="f_dock"
    type="continuous">
    <origin
      xyz="-0.00534999999999996 0 -0.0215593320349417"
      rpy="3.14159265358979 0 3.03104582528322" />
    <parent
      link="f_servo" />
    <child
      link="f_dock" />
    <axis
      xyz="0 0 1" />
  </joint>
  <link
    name="f_plate">
    <inertial>
      <origin
        xyz="0.000309399759430555 -0.00144767614728277 0.000962372542853741"
        rpy="0 0 0" />
      <mass
        value="0.00231351779814661" />
      <inertia
        ixx="1.82919980797035E-07"
        ixy="-1.28250660235226E-09"
        ixz="-2.40540462265919E-11"
        iyy="7.76041593777085E-07"
        iyz="1.24847634322208E-09"
        izz="9.5744099737356E-07" />
    </inertial>
    <visual>
      <origin
        xyz="0 0 0"
        rpy="0 0 0" />
      <geometry>
        <mesh
          filename="meshes/f_plate.STL" />
      </geometry>
      <material
        name="White"/>
    </visual>
    <collision>
      <origin
        xyz="0 0 0"
        rpy="0 0 0" />
      <geometry>
        <mesh
          filename="meshes/f_plate.STL" />
      </geometry>
    </collision>
  </link>
  <joint
    name="f_plate"
    type="fixed">
    <origin
      xyz="0.00710981547880829 0.0247871496673297 0.02925"
      rpy="0.279335238189619 1.5707963267949 0" />
    <parent
      link="r_plate" />
    <child
      link="f_plate" />
    <axis
      xyz="0 0 0" />
  </joint>
  <link
    name="l_plate">
    <inertial>
      <origin
        xyz="0.036453781512605 0.0225 0.001"
        rpy="0 0 0" />
      <mass
        value="0.00563834139292079" />
      <inertia
        ixx="9.18566945337334E-07"
        ixy="-2.20216452907176E-07"
        ixz="1.38007884533215E-26"
        iyy="1.67797643505038E-06"
        iyz="1.68685462267611E-24"
        izz="2.59278448612577E-06" />
    </inertial>
    <visual>
      <origin
        xyz="0 0 0"
        rpy="0 0 0" />
      <geometry>
        <mesh
          filename="meshes/l_plate.STL" />
      </geometry>
      <material
        name="White"/>
    </visual>
    <collision>
      <origin
        xyz="0 0 0"
        rpy="0 0 0" />
      <geometry>
        <mesh
          filename="meshes/l_plate.STL" />
      </geometry>
    </collision>
  </link>
  <joint
    name="l_plate"
    type="fixed">
    <origin
      xyz="-0.015594256799817 -0.0766777315109957 0.0338985670725845"
      rpy="1.5707963267949 0 0" />
    <parent
      link="base_link" />
    <child
      link="l_plate" />
    <axis
      xyz="0 0 0" />
  </joint>
  <link
    name="upper_pin">
    <inertial>
      <origin
        xyz="-3.46944695195361E-18 0 0.0279"
        rpy="0 0 0" />
      <mass
        value="0.000238824" />
      <inertia
        ixx="6.204727128E-08"
        ixy="0"
        ixz="2.00749775529513E-24"
        iyy="6.204727128E-08"
        iyz="3.30660373280005E-27"
        izz="1.59216000000001E-10" />
    </inertial>
    <visual>
      <origin
        xyz="0 0 0"
        rpy="0 0 0" />
      <geometry>
        <mesh
          filename="meshes/upper_pin.STL" />
      </geometry>
      <material
        name="Red"/>
    </visual>
    <collision>
      <origin
        xyz="0 0 0"
        rpy="0 0 0" />
      <geometry>
        <mesh
          filename="meshes/upper_pin.STL" />
      </geometry>
    </collision>
  </link>
  <joint
    name="upper_pin"
    type="fixed">
    <origin
      xyz="0.045176 0.035576 -0.056"
      rpy="0 0 -0.2791" />
    <parent
      link="l_plate" />
    <child
      link="upper_pin" />
    <axis
      xyz="0 0 0" />
  </joint>
  <link
    name="b_servo">
    <inertial>
      <origin
        xyz="-0.00036971681486659 -3.523963099758E-05 -0.00131147869095147"
        rpy="0 0 0" />
      <mass
        value="0.00677100577989105" />
      <inertia
        ixx="4.31149668793827E-07"
        ixy="8.8222281090352E-11"
        ixz="-3.1090472607926E-08"
        iyy="6.71938565978268E-07"
        iyz="1.0633490626013E-09"
        izz="3.9196741868065E-07" />
    </inertial>
    <visual>
      <origin
        xyz="0 0 0"
        rpy="0 0 0" />
      <geometry>
        <mesh
          filename="meshes/b_servo.STL" />
      </geometry>
      <material
        name="DBlue"/>
    </visual>
    <collision>
      <origin
        xyz="0 0 0"
        rpy="0 0 0" />
      <geometry>
        <mesh
          filename="meshes/b_servo.STL" />
      </geometry>
    </collision>
  </link>
  <joint
    name="b_servo"
    type="fixed">
    <origin
      xyz="0.0034656966666195 -0.00820924646147805 0.0226525215937532"
      rpy="-1.57079632679489 1.51354276544107 1.57056578752365" />
    <parent
      link="upper_pin" />
    <child
      link="b_servo" />
    <axis
      xyz="0 0 0" />
  </joint>
  <link
    name="b_dock">
    <inertial>
      <origin
        xyz="-0.000583720901506657 -6.93889390390723E-18 0.0005977118273887"
        rpy="0 0 0" />
      <mass
        value="0.000956519229010847" />
      <inertia
        ixx="3.43726720881399E-08"
        ixy="4.96308367531817E-24"
        ixz="9.64128228028072E-10"
        iyy="3.45134904910005E-08"
        iyz="-1.15666401227185E-23"
        izz="6.75077500977736E-08" />
    </inertial>
    <visual>
      <origin
        xyz="0 0 0"
        rpy="0 0 0" />
      <geometry>
        <mesh
          filename="meshes/b_dock.STL" />
      </geometry>
      <material
        name="LBlue"/>
    </visual>
    <collision>
      <origin
        xyz="0 0 0"
        rpy="0 0 0" />
      <geometry>
        <mesh
          filename="meshes/b_dock.STL" />
      </geometry>
    </collision>
  </link>
  <joint
    name="b_dock"
    type="continuous">
    <origin
      xyz="-0.00535000000000001 0 -0.0215593320349418"
      rpy="3.14159265358979 0 -2.35638402492922" />
    <parent
      link="b_servo" />
    <child
      link="b_dock" />
    <axis
      xyz="0 0 1" />
  </joint>
  <link
    name="top_plate">
    <inertial>
      <origin
        xyz="6.93889390390723E-18 0.00122555734799465 1.38777878078145E-17"
        rpy="0 0 0" />
      <mass
        value="0.00602026632101009" />
      <inertia
        ixx="1.29548427079343E-06"
        ixy="4.36959432062381E-23"
        ixz="1.82692972222254E-13"
        iyy="2.23546832291566E-06"
        iyz="6.64106438616836E-24"
        izz="9.4621327600451E-07" />
    </inertial>
    <visual>
      <origin
        xyz="0 0 0"
        rpy="0 0 0" />
      <geometry>
        <mesh
          filename="meshes/top_plate.STL" />
      </geometry>
      <material
        name="White"/>
    </visual>
    <collision>
      <origin
        xyz="0 0 0"
        rpy="0 0 0" />
      <geometry>
        <mesh
          filename="meshes/top_plate.STL" />
      </geometry>
    </collision>
  </link>
  <joint
    name="top_plate"
    type="fixed">
    <origin
      xyz="0.042248384032793 0.045 -0.028"
      rpy="0 0 0" />
    <parent
      link="l_plate" />
    <child
      link="top_plate" />
    <axis
      xyz="0 0 0" />
  </joint>
  <link
    name="tbr_motor">
    <inertial>
      <origin
        xyz="1.38777878078145E-17 6.93889390390723E-18 0.0106870527000651"
        rpy="0 0 0" />
      <mass
        value="0.000645828982770904" />
      <inertia
        ixx="2.61519018844216E-08"
        ixy="2.06795153138257E-25"
        ixz="1.24651660289363E-23"
        iyy="2.61519018844215E-08"
        iyz="-9.73446627734705E-25"
        izz="2.86716606772477E-09" />
    </inertial>
    <visual>
      <origin
        xyz="0 0 0"
        rpy="0 0 0" />
      <geometry>
        <mesh
          filename="meshes/tbr_motor.STL" />
      </geometry>
      <material
        name="Green"/>
    </visual>
    <collision>
      <origin
        xyz="0 0 0"
        rpy="0 0 0" />
      <geometry>
        <mesh
          filename="meshes/tbr_motor.STL" />
      </geometry>
    </collision>
  </link>
  <joint
    name="tbr_motor"
    type="fixed">
    <origin
      xyz="0.0178826765348059 -0.00299999999999999 -0.000144283776645951"
      rpy="3.14159265358979 0 1.46819705601191" />
    <parent
      link="top_plate" />
    <child
      link="tbr_motor" />
    <axis
      xyz="0 0 0" />
  </joint>
  <link
    name="tbr_wheel">
    <inertial>
      <origin
        xyz="-6.93889390390723E-18 -1.38777878078145E-17 -0.0025"
        rpy="0 0 0" />
      <mass
        value="0.000681713039458371" />
      <inertia
        ixx="8.90885323732182E-09"
        ixy="-1.83332255573129E-43"
        ixz="1.4751387590529E-25"
        iyy="8.90885323732182E-09"
        iyz="-2.31915303300036E-41"
        izz="1.49772354769004E-08" />
    </inertial>
    <visual>
      <origin
        xyz="0 0 0"
        rpy="0 0 0" />
      <geometry>
        <mesh
          filename="meshes/tbr_wheel.STL" />
      </geometry>
      <material
        name="Black"/>
    </visual>
    <collision>
      <origin
        xyz="0 0 0"
        rpy="0 0 0" />
      <geometry>
        <mesh
          filename="meshes/tbr_wheel.STL" />
      </geometry>
    </collision>
  </link>
  <joint
    name="tbr_wheel"
    type="continuous">
    <origin
      xyz="0 0 0.021"
      rpy="3.1416 0 1.4682" />
    <parent
      link="tbr_motor" />
    <child
      link="tbr_wheel" />
    <axis
      xyz="0 0 1" />
  </joint>
  <link
    name="tbl_motor">
    <inertial>
      <origin
        xyz="1.38777878078145E-17 0 0.0106870527000651"
        rpy="0 0 0" />
      <mass
        value="0.000645828982770904" />
      <inertia
        ixx="2.61519018844216E-08"
        ixy="0"
        ixz="-7.73061443086642E-25"
        iyy="2.61519018844216E-08"
        iyz="-3.02895648981018E-26"
        izz="2.86716606772477E-09" />
    </inertial>
    <visual>
      <origin
        xyz="0 0 0"
        rpy="0 0 0" />
      <geometry>
        <mesh
          filename="meshes/tbl_motor.STL" />
      </geometry>
      <material
        name="Green"/>
    </visual>
    <collision>
      <origin
        xyz="0 0 0"
        rpy="0 0 0" />
      <geometry>
        <mesh
          filename="meshes/tbl_motor.STL" />
      </geometry>
    </collision>
  </link>
  <joint
    name="tbl_motor"
    type="fixed">
    <origin
      xyz="0.0178826765348059 -0.00299999999999999 -0.000144283776645951"
      rpy="0 0 -0.997183454252289" />
    <parent
      link="top_plate" />
    <child
      link="tbl_motor" />
    <axis
      xyz="0 0 1" />
  </joint>
  <link
    name="tbl_wheel">
    <inertial>
      <origin
        xyz="-1.38777878078145E-17 0 0.0025"
        rpy="0 0 0" />
      <mass
        value="0.000681713039458371" />
      <inertia
        ixx="8.90885323732183E-09"
        ixy="-1.03397576569128E-25"
        ixz="-6.16325661004308E-25"
        iyy="8.90885323732182E-09"
        iyz="4.68312405634221E-26"
        izz="1.49772354769004E-08" />
    </inertial>
    <visual>
      <origin
        xyz="0 0 0"
        rpy="0 0 0" />
      <geometry>
        <mesh
          filename="meshes/tbl_wheel.STL" />
      </geometry>
      <material
        name="Black"/>
    </visual>
    <collision>
      <origin
        xyz="0 0 0"
        rpy="0 0 0" />
      <geometry>
        <mesh
          filename="meshes/tbl_wheel.STL" />
      </geometry>
    </collision>
  </link>
  <joint
    name="tbl_wheel"
    type="continuous">
    <origin
      xyz="0 0 0.021"
      rpy="0 0 1.10845521806602" />
    <parent
      link="tbl_motor" />
    <child
      link="tbl_wheel" />
    <axis
      xyz="0 0 1" />
  </joint>
  <link
    name="tfr_motor">
    <inertial>
      <origin
        xyz="-3.46944695195361E-18 0 0.0106870527000651"
        rpy="0 0 0" />
      <mass
        value="0.000645828982770904" />
      <inertia
        ixx="2.61519018844216E-08"
        ixy="-2.06795153138257E-25"
        ixz="1.51436649401199E-24"
        iyy="2.61519018844216E-08"
        iyz="3.80279204495365E-25"
        izz="2.86716606772477E-09" />
    </inertial>
    <visual>
      <origin
        xyz="0 0 0"
        rpy="0 0 0" />
      <geometry>
        <mesh
          filename="meshes/tfr_motor.STL" />
      </geometry>
      <material
        name="Green"/>
    </visual>
    <collision>
      <origin
        xyz="0 0 0"
        rpy="0 0 0" />
      <geometry>
        <mesh
          filename="meshes/tfr_motor.STL" />
      </geometry>
    </collision>
  </link>
  <joint
    name="tfr_motor"
    type="fixed">
    <origin
      xyz="-0.0194941929617864 -0.003 -2.24534021392858E-05"
      rpy="3.14159265358979 0 0.106028806705873" />
    <parent
      link="top_plate" />
    <child
      link="tfr_motor" />
    <axis
      xyz="0 0 1" />
  </joint>
  <link
    name="tfr_wheel">
    <inertial>
      <origin
        xyz="-2.86229373536173E-17 -1.38777878078145E-17 -0.0025"
        rpy="0 0 0" />
      <mass
        value="0.000681713039458371" />
      <inertia
        ixx="8.90885323732182E-09"
        ixy="-1.83332255573129E-43"
        ixz="1.4751387590529E-25"
        iyy="8.90885323732182E-09"
        iyz="-2.31915303300036E-41"
        izz="1.49772354769004E-08" />
    </inertial>
    <visual>
      <origin
        xyz="0 0 0"
        rpy="0 0 0" />
      <geometry>
        <mesh
          filename="meshes/tfr_wheel.STL" />
      </geometry>
      <material
        name="Black"/>
    </visual>
    <collision>
      <origin
        xyz="0 0 0"
        rpy="0 0 0" />
      <geometry>
        <mesh
          filename="meshes/tfr_wheel.STL" />
      </geometry>
    </collision>
  </link>
  <joint
    name="tfr_wheel"
    type="continuous">
    <origin
      xyz="0 0 0.021"
      rpy="3.14159265358979 0 0.106028806705873" />
    <parent
      link="tfr_motor" />
    <child
      link="tfr_wheel" />
    <axis
      xyz="0 0 1" />
  </joint>
  <link
    name="tfl_motor">
    <inertial>
      <origin
        xyz="-3.46944695195361E-18 1.38777878078145E-17 0.0106870527000651"
        rpy="0 0 0" />
      <mass
        value="0.000645828982770904" />
      <inertia
        ixx="2.61519018844216E-08"
        ixy="-1.08495879687389E-45"
        ixz="1.57418999866429E-25"
        iyy="2.61519018844216E-08"
        iyz="-4.35365143856206E-41"
        izz="2.86716606772477E-09" />
    </inertial>
    <visual>
      <origin
        xyz="0 0 0"
        rpy="0 0 0" />
      <geometry>
        <mesh
          filename="meshes/tfl_motor.STL" />
      </geometry>
      <material
        name="Green"/>
    </visual>
    <collision>
      <origin
        xyz="0 0 0"
        rpy="0 0 0" />
      <geometry>
        <mesh
          filename="meshes/tfl_motor.STL" />
      </geometry>
    </collision>
  </link>
  <joint
    name="tfl_motor"
    type="fixed">
    <origin
      xyz="-0.0194941929617864 -0.003 -2.24534021392858E-05"
      rpy="0 0 0" />
    <parent
      link="top_plate" />
    <child
      link="tfl_motor" />
    <axis
      xyz="0 0 0" />
  </joint>
  <link
    name="tfl_wheel">
    <inertial>
      <origin
        xyz="0 0 0.0025"
        rpy="0 0 0" />
      <mass
        value="0.000681713039458372" />
      <inertia
        ixx="8.90885323732182E-09"
        ixy="-1.83332255573151E-43"
        ixz="3.92123002955742E-41"
        iyy="8.90885323732183E-09"
        iyz="-2.31915303300036E-41"
        izz="1.49772354769004E-08" />
    </inertial>
    <visual>
      <origin
        xyz="0 0 0"
        rpy="0 0 0" />
      <geometry>
        <mesh
          filename="meshes/tfl_wheel.STL" />
      </geometry>
      <material
        name="Black"/>
    </visual>
    <collision>
      <origin
        xyz="0 0 0"
        rpy="0 0 0" />
      <geometry>
        <mesh
          filename="meshes/tfl_wheel.STL" />
      </geometry>
    </collision>
  </link>
  <joint
    name="tfl_wheel"
    type="continuous">
    <origin
      xyz="0 0 0.021"
      rpy="0 0 0" />
    <parent
      link="tfl_motor" />
    <child
      link="tfl_wheel" />
    <axis
      xyz="0 0 1" />
  </joint>
  <link
    name="b_plate">
    <inertial>
      <origin
        xyz="0.000310999719843649 0.00104215151184568 0.00112182676306154"
        rpy="0 0 0" />
      <mass
        value="0.00230993788046124" />
      <inertia
        ixx="1.84355003500156E-07"
        ixy="4.92118238422235E-10"
        ixz="6.42000422942462E-11"
        iyy="7.76879023285739E-07"
        iyz="-1.26888192426726E-08"
        izz="9.57966269872945E-07" />
    </inertial>
    <visual>
      <origin
        xyz="0 0 0"
        rpy="0 0 0" />
      <geometry>
        <mesh
          filename="meshes/b_plate.STL" />
      </geometry>
      <material
        name="White"/>
    </visual>
    <collision>
      <origin
        xyz="0 0 0"
        rpy="0 0 0" />
      <geometry>
        <mesh
          filename="meshes/b_plate.STL" />
      </geometry>
    </collision>
  </link>
  <joint
    name="b_plate"
    type="fixed">
    <origin
      xyz="0.06388 0.020927 -0.02875"
      rpy="-1.3638 1.5708 -1.5667" />
    <parent
      link="l_plate" />
    <child
      link="b_plate" />
    <axis
      xyz="0 0 0" />
  </joint>
</robot>